Workbook

Sheet Infra Device (stock) 
A1: No. | B1: Item | C1: Type Device | D1: Stock | E1: Note | F1: sw
A2: 1 | B2: Ram 4Gb | C2: Ram | D2: =SUMIFS('Infra Device (transactions)'!F:F,'Infra Device (transactions)'!B:B,B2,'Infra Device (transactions)'!E:E,"In") - SUMIFS('Infra Device (transactions)'!F:F,'Infra Device (transactions)'!B:B,B2,'Infra Device (transactions)'!E:E,"Out") -> 1
A3: =A2+1 -> 2 | B3: Maken MK410 | C3: Cash Drawer | D3: =SUMIFS('Infra Device (transactions)'!F:F,'Infra Device (transactions)'!B:B,B3,'Infra Device (transactions)'!E:E,"In") - SUMIFS('Infra Device (transactions)'!F:F,'Infra Device (transactions)'!B:B,B3,'Infra Device (transactions)'!E:E,"Out") -> 7
A4: =A3+1 -> 3 | B4: Antech | C4: Cash Drawer | D4: =SUMIFS('Infra Device (transactions)'!F:F,'Infra Device (transactions)'!B:B,B4,'Infra Device (transactions)'!E:E,"In") - SUMIFS('Infra Device (transactions)'!F:F,'Infra Device (transactions)'!B:B,B4,'Infra Device (transactions)'!E:E,"Out") -> 2
A5: =A4+1 -> 4 | B5: Poscom | C5: Cash Drawer | D5: =SUMIFS('Infra Device (transactions)'!F:F,'Infra Device (transactions)'!B:B,B5,'Infra Device (transactions)'!E:E,"In") - SUMIFS('Infra Device (transactions)'!F:F,'Infra Device (transactions)'!B:B,B5,'Infra Device (transactions)'!E:E,"Out") -> 4
A6: =A5+1 -> 5 | B6: KA410 | C6: Cash Drawer | D6: =SUMIFS('Infra Device (transactions)'!F:F,'Infra Device (transactions)'!B:B,B6,'Infra Device (transactions)'!E:E,"In") - SUMIFS('Infra Device (transactions)'!F:F,'Infra Device (transactions)'!B:B,B6,'Infra Device (transactions)'!E:E,"Out") -> 1
A7: =A6+1 -> 6 | B7: Cash drawer of mall | C7: Cash Drawer | D7: =SUMIFS('Infra Device (transactions)'!F:F,'Infra Device (transactions)'!B:B,B7,'Infra Device (transactions)'!E:E,"In") - SUMIFS('Infra Device (transactions)'!F:F,'Infra Device (transactions)'!B:B,B7,'Infra Device (transactions)'!E:E,"Out") -> 2
A8: =A7+1 -> 7 | B8: Epson L850 | C8: Color Printer | D8: =SUMIFS('Infra Device (transactions)'!F:F,'Infra Device (transactions)'!B:B,B8,'Infra Device (transactions)'!E:E,"In") - SUMIFS('Infra Device (transactions)'!F:F,'Infra Device (transactions)'!B:B,B8,'Infra Device (transactions)'!E:E,"Out") -> 1
A9: =A8+1 -> 8 | B9: HP Laserjet P2055D | C9: A4 Printer | D9: =SUMIFS('Infra Device (transactions)'!F:F,'Infra Device (transactions)'!B:B,B9,'Infra Device (transactions)'!E:E,"In") - SUMIFS('Infra Device (transactions)'!F:F,'Infra Device (transactions)'!B:B,B9,'Infra Device (transactions)'!E:E,"Out") -> 1
A10: =A9+1 -> 9 | B10: Epson TM-U220A | C10: Bill Printer | D10: =SUMIFS('Infra Device (transactions)'!F:F,'Infra Device (transactions)'!B:B,B10,'Infra Device (transactions)'!E:E,"In") - SUMIFS('Infra Device (transactions)'!F:F,'Infra Device (transactions)'!B:B,B10,'Infra Device (transactions)'!E:E,"Out") -> 3
A11: =A10+1 -> 10 | B11: Canon L11121E | C11: A4 Printer | D11: =SUMIFS('Infra Device (transactions)'!F:F,'Infra Device (transactions)'!B:B,B11,'Infra Device (transactions)'!E:E,"In") - SUMIFS('Infra Device (transactions)'!F:F,'Infra Device (transactions)'!B:B,B11,'Infra Device (transactions)'!E:E,"Out") -> 1
A12: =A11+1 -> 11 | B12: Canon LBP 2900 | C12: A4 Printer | D12: =SUMIFS('Infra Device (transactions)'!F:F,'Infra Device (transactions)'!B:B,B12,'Infra Device (transactions)'!E:E,"In") - SUMIFS('Infra Device (transactions)'!F:F,'Infra Device (transactions)'!B:B,B12,'Infra Device (transactions)'!E:E,"Out") -> 7
A13: =A12+1 -> 12 | B13: HP Laserjet pro M15w | C13: A4 Printer | D13: =SUMIFS('Infra Device (transactions)'!F:F,'Infra Device (transactions)'!B:B,B13,'Infra Device (transactions)'!E:E,"In") - SUMIFS('Infra Device (transactions)'!F:F,'Infra Device (transactions)'!B:B,B13,'Infra Device (transactions)'!E:E,"Out") -> 2
A14: =A13+1 -> 13 | B14: HP Laserjet pro M12w | C14: A4 Printer | D14: =SUMIFS('Infra Device (transactions)'!F:F,'Infra Device (transactions)'!B:B,B14,'Infra Device (transactions)'!E:E,"In") - SUMIFS('Infra Device (transactions)'!F:F,'Infra Device (transactions)'!B:B,B14,'Infra Device (transactions)'!E:E,"Out") -> 2
A15: =A14+1 -> 14 | B15: HP Pavilion 550-029I | C15: Desktop | D15: =SUMIFS('Infra Device (transactions)'!F:F,'Infra Device (transactions)'!B:B,B15,'Infra Device (transactions)'!E:E,"In") - SUMIFS('Infra Device (transactions)'!F:F,'Infra Device (transactions)'!B:B,B15,'Infra Device (transactions)'!E:E,"Out") -> 2 | E15: Location: Pantry room
A16: =A15+1 -> 15 | B16: PC-none use | C16: Desktop | D16: =SUMIFS('Infra Device (transactions)'!F:F,'Infra Device (transactions)'!B:B,B16,'Infra Device (transactions)'!E:E,"In") - SUMIFS('Infra Device (transactions)'!F:F,'Infra Device (transactions)'!B:B,B16,'Infra Device (transactions)'!E:E,"Out") -> 4 | E16: Location: Pantry room
A17: =A16+1 -> 16 | B17: HDD 500Gb | C17: hard disk drive | D17: =SUMIFS('Infra Device (transactions)'!F:F,'Infra Device (transactions)'!B:B,B17,'Infra Device (transactions)'!E:E,"In") - SUMIFS('Infra Device (transactions)'!F:F,'Infra Device (transactions)'!B:B,B17,'Infra Device (transactions)'!E:E,"Out") -> 7
A18: =A17+1 -> 17 | B18: HP ProDesk 400 G3 DM | C18: Mini Pc | D18: =SUMIFS('Infra Device (transactions)'!F:F,'Infra Device (transactions)'!B:B,B18,'Infra Device (transactions)'!E:E,"In") - SUMIFS('Infra Device (transactions)'!F:F,'Infra Device (transactions)'!B:B,B18,'Infra Device (transactions)'!E:E,"Out") -> 7
A19: =A18+1 -> 18 | B19: HP 280 G3 MT | C19: Desktop | D19: =SUMIFS('Infra Device (transactions)'!F:F,'Infra Device (transactions)'!B:B,B19,'Infra Device (transactions)'!E:E,"In") - SUMIFS('Infra Device (transactions)'!F:F,'Infra Device (transactions)'!B:B,B19,'Infra Device (transactions)'!E:E,"Out") -> 2
A20: =A19+1 -> 19 | B20: HP 190V | C20: Monitor | D20: =SUMIFS('Infra Device (transactions)'!F:F,'Infra Device (transactions)'!B:B,B20,'Infra Device (transactions)'!E:E,"In") - SUMIFS('Infra Device (transactions)'!F:F,'Infra Device (transactions)'!B:B,B20,'Infra Device (transactions)'!E:E,"Out") -> 10
A21: =A20+1 -> 20 | B21: HP 194V | C21: Monitor | D21: =SUMIFS('Infra Device (transactions)'!F:F,'Infra Device (transactions)'!B:B,B21,'Infra Device (transactions)'!E:E,"In") - SUMIFS('Infra Device (transactions)'!F:F,'Infra Device (transactions)'!B:B,B21,'Infra Device (transactions)'!E:E,"Out") -> 3
A22: =A21+1 -> 21 | B22: AOC 1619Sw | C22: Monitor | D22: =SUMIFS('Infra Device (transactions)'!F:F,'Infra Device (transactions)'!B:B,B22,'Infra Device (transactions)'!E:E,"In") - SUMIFS('Infra Device (transactions)'!F:F,'Infra Device (transactions)'!B:B,B22,'Infra Device (transactions)'!E:E,"Out") -> 1
A23: =A22+1 -> 22 | B23: AOC 931Swl | C23: Monitor | D23: =SUMIFS('Infra Device (transactions)'!F:F,'Infra Device (transactions)'!B:B,B23,'Infra Device (transactions)'!E:E,"In") - SUMIFS('Infra Device (transactions)'!F:F,'Infra Device (transactions)'!B:B,B23,'Infra Device (transactions)'!E:E,"Out") -> 2
A24: =A23+1 -> 23 | B24: Samsung B1930N | C24: Monitor | D24: =SUMIFS('Infra Device (transactions)'!F:F,'Infra Device (transactions)'!B:B,B24,'Infra Device (transactions)'!E:E,"In") - SUMIFS('Infra Device (transactions)'!F:F,'Infra Device (transactions)'!B:B,B24,'Infra Device (transactions)'!E:E,"Out") -> 1
A25: =A24+1 -> 24 | B25: Acer P196HQL | C25: Monitor | D25: =SUMIFS('Infra Device (transactions)'!F:F,'Infra Device (transactions)'!B:B,B25,'Infra Device (transactions)'!E:E,"In") - SUMIFS('Infra Device (transactions)'!F:F,'Infra Device (transactions)'!B:B,B25,'Infra Device (transactions)'!E:E,"Out") -> 1
A26: =A25+1 -> 25 | B26: D-LINK DIR-619L | C26: Router | D26: =SUMIFS('Infra Device (transactions)'!F:F,'Infra Device (transactions)'!B:B,B26,'Infra Device (transactions)'!E:E,"In") - SUMIFS('Infra Device (transactions)'!F:F,'Infra Device (transactions)'!B:B,B26,'Infra Device (transactions)'!E:E,"Out") -> 0
A27: =A26+1 -> 26 | B27: HDMI to HDMI (3M) | C27: HDMI Cable | D27: =SUMIFS('Infra Device (transactions)'!F:F,'Infra Device (transactions)'!B:B,B27,'Infra Device (transactions)'!E:E,"In") - SUMIFS('Infra Device (transactions)'!F:F,'Infra Device (transactions)'!B:B,B27,'Infra Device (transactions)'!E:E,"Out") -> 2
A28: =A27+1 -> 27 | B28: Lion (3 Port) | C28: Power socket | D28: =SUMIFS('Infra Device (transactions)'!F:F,'Infra Device (transactions)'!B:B,B28,'Infra Device (transactions)'!E:E,"In") - SUMIFS('Infra Device (transactions)'!F:F,'Infra Device (transactions)'!B:B,B28,'Infra Device (transactions)'!E:E,"Out") -> 1
... A147: =A146+1 -> 146 | B147: Dell E2216HV | C147: Monitor | D147: =SUMIFS('Infra Device (transactions)'!F:F,'Infra Device (transactions)'!B:B,B147,'Infra Device (transactions)'!E:E,"In") - SUMIFS('Infra Device (transactions)'!F:F,'Infra Device (transactions)'!B:B,B147,'Infra Device (transactions)'!E:E,"Out") -> 1
A148: 147 | B148: TP link tl sf1008d | C148: Switch | D148: =SUMIFS('Infra Device (transactions)'!F:F,'Infra Device (transactions)'!B:B,B148,'Infra Device (transactions)'!E:E,"In") - SUMIFS('Infra Device (transactions)'!F:F,'Infra Device (transactions)'!B:B,B148,'Infra Device (transactions)'!E:E,"Out") -> 1
A149: =A148+1 -> 148 | B149: USB Wifi TP-Link AC1300 | C149: USB Wifi TP-Link | D149: =SUMIFS('Infra Device (transactions)'!F:F,'Infra Device (transactions)'!B:B,B149,'Infra Device (transactions)'!E:E,"In") - SUMIFS('Infra Device (transactions)'!F:F,'Infra Device (transactions)'!B:B,B149,'Infra Device (transactions)'!E:E,"Out") -> 1
A150: =A149+1 -> 149 | B150: KPOS-VFD-220U | C150: Pole Display | D150: =SUMIFS('Infra Device (transactions)'!F:F,'Infra Device (transactions)'!B:B,B150,'Infra Device (transactions)'!E:E,"In") - SUMIFS('Infra Device (transactions)'!F:F,'Infra Device (transactions)'!B:B,B150,'Infra Device (transactions)'!E:E,"Out") -> 1
A151: =A150+1 -> 150 | B151: Wifi UBIQUITI UniFi | C151: Access Point | D151: =SUMIFS('Infra Device (transactions)'!F:F,'Infra Device (transactions)'!B:B,B151,'Infra Device (transactions)'!E:E,"In") - SUMIFS('Infra Device (transactions)'!F:F,'Infra Device (transactions)'!B:B,B151,'Infra Device (transactions)'!E:E,"Out") -> 16
A152: =A151+1 -> 151 | B152: Ugreen Silent MU006 Wireless Mouse | C152: mouse | D152: =SUMIFS('Infra Device (transactions)'!F:F,'Infra Device (transactions)'!B:B,B152,'Infra Device (transactions)'!E:E,"In") - SUMIFS('Infra Device (transactions)'!F:F,'Infra Device (transactions)'!B:B,B152,'Infra Device (transactions)'!E:E,"Out") -> 0
A153: =A152+1 -> 152 | B153: Ipad Air 13-inch(M3) | C153: Tablet | D153: =SUMIFS('Infra Device (transactions)'!F:F,'Infra Device (transactions)'!B:B,B153,'Infra Device (transactions)'!E:E,"In") - SUMIFS('Infra Device (transactions)'!F:F,'Infra Device (transactions)'!B:B,B153,'Infra Device (transactions)'!E:E,"Out") -> 0 | E153: only for VN Asics
A154: =A153+1 -> 153 | B154: RUIJIE REEYE RG-EW1200G Pro | C154: Access Point | D154: =SUMIFS('Infra Device (transactions)'!F:F,'Infra Device (transactions)'!B:B,B154,'Infra Device (transactions)'!E:E,"In") - SUMIFS('Infra Device (transactions)'!F:F,'Infra Device (transactions)'!B:B,B154,'Infra Device (transactions)'!E:E,"Out") -> 0
A155: =A154+1 -> 154 | B155: Desktop HP PRO MINI 400 G9 | C155: Mini PC | D155: =SUMIFS('Infra Device (transactions)'!F:F,'Infra Device (transactions)'!B:B,B155,'Infra Device (transactions)'!E:E,"In") - SUMIFS('Infra Device (transactions)'!F:F,'Infra Device (transactions)'!B:B,B155,'Infra Device (transactions)'!E:E,"Out") -> 1
A156: =A155+1 -> 155 | B156: aruba ap 535 jz336a | C156: Access Point | D156: =SUMIFS('Infra Device (transactions)'!F:F,'Infra Device (transactions)'!B:B,B156,'Infra Device (transactions)'!E:E,"In") - SUMIFS('Infra Device (transactions)'!F:F,'Infra Device (transactions)'!B:B,B156,'Infra Device (transactions)'!E:E,"Out") -> 7
A157: =A156+1 -> 156 | B157: SATO CL4NX Plus | C157: Printer | D157: =SUMIFS('Infra Device (transactions)'!F:F,'Infra Device (transactions)'!B:B,B157,'Infra Device (transactions)'!E:E,"In") - SUMIFS('Infra Device (transactions)'!F:F,'Infra Device (transactions)'!B:B,B157,'Infra Device (transactions)'!E:E,"Out") -> 2
A158: =A157+1 -> 157 | B158: HP V22 | C158: monitor | D158: =SUMIFS('Infra Device (transactions)'!F:F,'Infra Device (transactions)'!B:B,B158,'Infra Device (transactions)'!E:E,"In") - SUMIFS('Infra Device (transactions)'!F:F,'Infra Device (transactions)'!B:B,B158,'Infra Device (transactions)'!E:E,"Out") -> 8
...

Sheet Infra Device (transactions)
A1: No. | B1: Item | C1: Description | D1: Date | E1: Transaction Type | F1: Quantity | G1: Unit | H1: Assigned | I1: Assign history | J1: Status | K1: S/N | L1: Remark
A2: 1 | B2: Ram 4Gb | D2: 16/02/2024 | E2: in | F2: 4 | G2: pcs | H2: Stock IT
A3: 2 | B3: Ram 4Gb | C3: upgrade linh.lengocmy's laptop | D3: 16/02/2024 | E3: out | F3: 1 | G3: pcs | H3: linh.lengocmy | L3: Broken: can't fix None-use: Don't use anymore and don't the status of device
A4: 3 | B4: Maken MK410 | D4: 22/02/2024 | E4: In | F4: 8 | G4: pcs | H4: Stock IT | K4: MK410221102420 MK410220300197 MK410211201000 MK410211201512 MK410220300423 MK410221102371 MK410221102347 MK410220300326
A5: 4 | B5: Antech | D5: 22/02/2024 | E5: In | F5: 1 | G5: pcs | H5: Stock IT | K5: DGAV141220180773 B5AT100009
A6: 5 | B6: Poscom | D6: 22/02/2024 | E6: In | F6: 2 | G6: pcs | H6: Stock IT | K6: 2020092533
A7: 6 | B7: KA410 | D7: 22/02/2024 | E7: In | F7: 1 | G7: pcs | H7: Stock IT | K7: 20230526081
A8: 7 | B8: Cash drawer of mall | C8: Quỳnh AM đóng nhầm cash drawer của smart city | D8: 22/02/2024 | E8: In | F8: 1 | G8: pcs | H8: Stock IT | K8: 200414009618
A9: 8 | B9: Epson L850 | C9: Broken -Mr.Dat confirmed can't fix because don't have replacement components | D9: 22/02/2024 | E9: In | F9: 1 | G9: pcs | H9: Stock IT | J9: Broken | K9: UTUY000488
A10: 9 | B10: HP Laserjet P2055D | C10: Broken -Mr.Dat confirmed can't fix because don't have replacement components | D10: 22/02/2024 | E10: In | F10: 1 | G10: pcs | H10: Stock IT | J10: Broken | K10: CNCJY00421
A11: 10 | B11: Epson TM-U220A | C11: Lose power supply, usb cable - Indo not use this model anymore (Mr.Dat confirmed) | D11: 22/02/2024 | E11: In | F11: 3 | G11: pcs | H11: Stock IT | J11: Broken | K11: L98F275060 L97F002416 L9CF300124
A12: 11 | B12: Canon L11121E | C12: Old | D12: 22/02/2024 | E12: In | F12: 1 | G12: pcs | H12: Stock IT | I12: VN14 | K12: NMYA744682
A13: 12 | B13: Canon LBP 2900 | C13: New, lô hàng satatech | D13: 22/02/2024 | E13: In | F13: 1 | G13: pcs | H13: Stock IT | K13: NMYA783808
A14: 13 | B14: HP Laserjet pro M15w | C14: Old | D14: 22/02/2024 | E14: In | F14: 1 | G14: pcs | H14: Stock IT | I14: VF02 | K14: VNC3K04690
A15: 14 | B15: HP Laserjet pro M15w | C15: Old | D15: 22/02/2024 | E15: In | F15: 1 | G15: pcs | H15: Stock IT | I15: PO02 | K15: VNC3K04070
A16: 15 | B16: HP Laserjet pro M15w | C16: Old | D16: 22/02/2024 | E16: In | F16: 1 | G16: pcs | H16: Stock IT | I16: VC01 | K16: VNC3K05078
A17: 16 | B17: HP Laserjet pro M12w | C17: Old | D17: 22/02/2024 | E17: In | F17: 1 | G17: pcs | H17: Stock IT | I17: ZV09-12 | K17: VNCW613481
A18: 17 | B18: Antech | C18: Old | D18: 22/02/2024 | E18: In | F18: 1 | G18: pcs | H18: Stock IT | I18: VF02 | K18: DGAV141220180609
A19: 18 | B19: HP Pavilion 550-029I | C19: Old | D19: 22/02/2024 | E19: In | F19: 1 | G19: pcs | H19: Location: Pantry room | I19: Un-known | J19: None-use | K19: 4CE5360DVB
A20: 19 | B20: PC-none use | C20: Don't know information - don't have any info on the case | D20: 22/02/2024 | E20: In | F20: 4 | G20: pcs | H20: Location: Pantry room | I20: Un-known | J20: None-use
A21: 20 | B21: HDD 500Gb | C21: Old | D21: 22/02/2024 | E21: In | F21: 1 | G21: pcs | H21: Stock IT | I21: PO01-Admin | J21: None-use | K21: W62LE31F
A22: 21 | B22: HDD 500Gb | C22: Old | D22: 22/02/2024 | E22: In | F22: 1 | G22: pcs | H22: Stock IT | I22: PO01-Pos2 | J22: None-use | K22: W62KW2KT
A23: 22 | B23: HDD 500Gb | C23: Old | D23: 22/02/2024 | E23: In | F23: 1 | G23: pcs | H23: Stock IT | I23: PO02-Pos1 | J23: None-use | K23: W62L7N1A
A24: 23 | B24: HDD 500Gb | C24: Old | D24: 22/02/2024 | E24: In | F24: 1 | G24: pcs | H24: Stock IT | I24: PO01-Server | J24: None-use | K24: W62LFH4H
A25: 24 | B25: HDD 500Gb | C25: Old | D25: 22/02/2024 | E25: In | F25: 1 | G25: pcs | H25: Stock IT | I25: PO01-POS | J25: None-use | K25: W62KWFS9
A26: 25 | B26: HDD 500Gb | C26: Old | D26: 22/02/2024 | E26: In | F26: 1 | G26: pcs | H26: Stock IT | I26: PO02-Pos2 | J26: None-use | K26: W62LFM8W
A27: 26 | B27: HDD 500Gb | C27: Old | D27: 22/02/2024 | E27: In | F27: 1 | G27: pcs | H27: Stock IT | I27: PO02-Server | J27: None-use | K27: W62L7N7S
A28: 27 | B28: HP ProDesk 400 G3 DM | C28: Bazzar | D28: 26/02/2024 | E28: In | F28: 1 | G28: pcs | H28: ZK05-ZW05-ZV05 | K28: 8CG7127F7Q
A29: 28 | B29: HP ProDesk 400 G3 DM | C29: Bazzar | D29: 26/02/2024 | E29: In | F29: 1 | G29: pcs | H29: ZV01-H103-H104 | K29: 8CG8105MSK
A30: 29 | B30: HP ProDesk 400 G3 DM | C30: Bazzar | D30: 26/02/2024 | E30: In | F30: 1 | G30: pcs | H30: H101-H102 | K30: 8CG75234Q2
A31: 30 | B31: HP 280 G3 MT | C31: none-info | D31: 26/02/2024 | E31: In | F31: 1 | G31: pcs | H31: None-info | K31: 4CE7385WT0
A32: 31 | B32: HP 190V | D32: 26/02/2024 | E32: In | F32: 1 | G32: pcs | H32: ZK05-ZW05-ZV05-ZV01-H103-H104-H101-H102 | K32: 1CR8420G66
A33: 32 | B33: HP 190V | D33: 26/02/2024 | E33: In | F33: 1 | G33: pcs | H33: VN17 | K33: 1CR82307D4
A34: 33 | B34: HP 190V | D34: 26/02/2024 | E34: In | F34: 1 | G34: pcs | H34: VF02 | K34: 1CR84126GF
A35: 34 | B35: HP 194V | C35: IT-BACKUP | D35: 26/02/2024 | E35: In | F35: 1 | G35: pcs | K35: 3CQ6361YDZ
A36: 35 | B36: HP 190V | C36: Mất đế | D36: 26/02/2024 | E36: In | F36: 1 | G36: pcs | H36: PO01 | K36: 1CR82307CY
A37: 36 | B37: HP 190V | C37: Mất đế | D37: 26/02/2024 | E37: In | F37: 1 | G37: pcs | H37: PO01 | K37: 1CR82307CJ
A38: 37 | B38: AOC 1619Sw | C38: Old | D38: 26/02/2024 | E38: In | F38: 1 | G38: pcs | K38: BMNB3JA000570
A39: 38 | B39: AOC 931Swl | C39: Old | D39: 26/02/2024 | E39: In | F39: 1 | G39: pcs | K39: CLCBCHA033328
A40: 39 | B40: Samsung B1930N | C40: Old | D40: 26/02/2024 | E40: In | F40: 1 | G40: pcs | K40: 1458HYTZ912979F
...

Sheet Mini PC status
A1: Asset Code | B1: Model | C1: Vendor | D1: Hardware | E1: Computer Name | F1: Serial number | G1: MAC Address LAN | H1: MAC Address WiFi | I1: OS | J1: Note
A2: VC01 | B2: ProDesk 400 G3 Mini | C2: HP | D2: CPUi5-7500T 2.7 GHz/RAM 8GB DDR4 2400 MHz(4x2) /SDD500 GB (VN17/SN:S7BWNJ0W745993K) | E2: x | F2: 8CG8105MSQ | G2: 10-E7-C6-08-74-27 | H2: 7A-5D-42-60-77-95 | I2: W10 | J2: K301-ADMIN
A3: VC03-Admin | B3: ProDesk 400 G3 Mini | C3: HP | D3: CPUi5-7500T 2.7 GHz/RAM 8GB DDR4 2400 MHz(4x2) /HDD500 GB | E3: x | F3: 8CG75206VW | H3: C8-09-A8-BC-32-11 | I3: W10 | J3: hư nguồn, usb
A4: P001-Admin | B4: ProDesk 400 G3 Mini | C4: HP | D4: CPUi5-7500T 2.7 GHz/RAM 12GB DDR4 2400 MHz(4x1, 8x1) /HDD500 GB | E4: x | F4: 8CGG75234QP | H4: C8-09-A8-DC-1F-B3 | I4: W10 | J4: lổi bios ko nhận usb, 2 cổng usb trước hư
A5: P002-Admin | B5: ProDesk 400 G3 Mini | C5: HP | D5: CPUi5-7500T 2.7 GHz/RAM 8GB DDR4 2400 MHz(4x2) /SSD500 GB(SN:S6P6NL0TC39331V) | E5: x | F5: 8CG8105N1T | G5: 10-E7-C6-08-72-F0 | H5: E0-9D-31-D3-FF-6D | I5: W10 | J5: VN15-ADMIN
A6: VF02-ADMIN | B6: ProDesk 400 G3 Mini | C6: HP | D6: CPUi5-7500T 2.7 GHz/RAM 8GB DDR4 2400 MHz(4x2) /HDD500 GB | E6: x | F6: 8CG8052W2H | G6: 10-E7-C6-01-40-83 | H6: 4E-FB-C8-A6-0B-49 | I6: w10 | J6: hư 1 cổng usb trước
A7: VN20-Admin | B7: Optiplex 3090 | C7: Dell | J7: Đang kím nguồn
A8: VN17 | J8: đang đóng store
A9: Bazzar
A10: Bazzar

Sheet Sheet1
A1: VN05 | B1: Converse Crescent mall | C1: Trần Phạm Minh Ngọc | D1: Supervisor | E1: 704447276 | F1: VO LAM MINH DAT
A2: VN07 | B2: Converse Nguyen Trai D1 | C2: Nguyễn Ngọc Thiện | D2: Supervisor | E2: 379932155 | F2: VO LAM MINH DAT
A3: VN16 | B3: Converse Ba Thang Hai D10 | C3: Nguyễn Thanh Danh | D3: Supervisor | E3: 931771497 | F3: VO LAM MINH DAT
A4: VN09 | B4: Converse Aeon Canary | C4: Đinh Hồng Hạnh | D4: Supervisor | E4: 965314912 | F4: DUONG QUANG MINH TUAN
A5: VN10 | B5: Converse Aeon Binh Tan | C5: Trần Thị Kim Huệ | D5: Supervisor | E5: 904187104 | F5: DUONG QUANG MINH TUAN
A6: VN08 | B6: Converse Hai Ba Trung D3 | C6: Huỳnh Văn Thiện | D6: Supervisor | E6: 328955231 | F6: VO LAM MINH DAT
A7: VN19 | B7: Converse Gold Coast | C7: Dương Anh Quốc | D7: Supervisor | E7: 898460922 | F7: VO LAM MINH DAT
A8: VN27 | B8: Converse CFS Quang Trung | C8: Nguyễn Văn Huy | D8: Store Manager | E8: 383438670 | F8: DAO DUC HUY
A9: VI03 | B9: Smiggle Estella | C9: Nguyễn Kim Phương Uyên | D9: Supervisor | E9: 876762396 | F9: DAO DUC HUY
A10: VA06 | B10: New Balance Crescent mall | C10: Chềnh Gia Hỷ | D10: Supervisor | E10: 366739361 | F10: VO LAM MINH DAT
A11: VA08 | B11: New Balance Diamond | C11: Nguyễn Hoàng Hiếu | D11: Supervisor | E11: 799411608 | F11: DUONG QUANG MINH TUAN
A12: VA01 | B12: New Balance Van Hanh Mall | C12: Tô Kim Hoàng | D12: Supervisor | E12: 903288823 | F12: DUONG QUANG MINH TUAN
... A29: VH02 | B29: Skechers Lotte Department | C29: Trần Đăng Khoa | D29: Supervisor | E29: 964960001 | F29: NGUYEN THI HONG NHUNG
A30: A001 | B30: Asics Lotte Mall | F30: NGUYEN THI HONG NHUNG
A31: VA19 | B31: New Balance Hanoi Center | F31: NGUYEN THI HONG NHUNG
A32: VO03 | B32: Foot Locker Hanoi Center | F32: NGUYEN THI HONG NHUNG
A33: VN28 | B33: Converse Hanoi Center | F33: NGUYEN THI HONG NHUNG
A34: VH01 | B34: Skechers Hanoi Center | F34: NGUYEN THI HONG NHUNG
A35: ZV32 | B35: Event Lotte Mall West Lake | C35: Nguyễn Thị Hồng Nhung | D35: AM | E35: 969230340 | F35: NGUYEN THI HONG NHUNG
